Workbook

Sheet 설계 요약
B2: 자동차 복합재 부품 텐덤금형 사출실험 DOE — 고정측 20런 (4×4 @60℃ + 40℃ 4런) / 이동측 2² 내포 (4런)
B3: 텐덤금형, 고정측 1캐비티 + 이동측 1캐비티. 고정측: 핫러너 온도 4수준 × 사출속도 4수준(금형온도 60℃) 16런 + 금형온도 40℃ 추가 4런 = 20조건. 이동측: 핫러너 온도·사출속도 2수준(2²) 4런만 측정하며, 모두 고정측 런에 포함되어 추가 성형 없이 시편 측정만 추가된다.
B5: 1. 인자 및 수준
B6: 인자 | C6: 수준 | D6: 수준 수 | E6: 코드값 | F6: 비고
B7: A. 핫러너 온도 (℃) | C7: 210 / 223 / 237 / 250 | D7: 4 | E7: −1 / −⅓ / ⅓ / 1 | F7: 핫러너 컨트롤러 설정, 두 파팅면 동일. 210–250℃를 정수로 등간격 근사(13·14·13℃). 승온·안정화 시간이 가장 긺 → 블록 인자
B8: B. 금형온도 (℃) | C8: 60 (주 설계 고정) / 40 (추가 4런) | D8: 2 | E8: 1 / −1 | F8: 주 설계 16런은 60℃ 고정. 40℃는 핫러너 온도 4수준 × 사출속도 80 mm/s에서만 추가 실험. 고정측·이동측 온조기 동일 설정
B9: C. 사출속도 (mm/s) | C9: 20 / 40 / 60 / 80 | D9: 4 | E9: −1 / −⅓ / ⅓ / 1 | F9: 두 파팅면 사출 프로파일 동일 설정. 변경 용이
B11: 2. 고정변수 (전 런 동일 설정)
B12: 고정변수 | C12: 설정값 | D12: 단위
B13: 보압 | C13: 최고사출압의 100% | D13: % | E13: 사출 시 최고압을 기준으로 100% 설정
B14: 보압시간 | C14: 6 | D14: s
B15: 계량거리 | C15: 86 | D15: mm
B16: V/P 전환 위치 | C16: 36 | D16: mm | E16: 속도→압력 전환(스크루 위치)
B17: 냉각시간 | C17: 60 | D17: s
B18: 배럴온도 | C18: 210 | D18: ℃ | E18: 핫러너 온도(인자 A)와 별개로 고정
B19: 노즐온도 | C19: 215 | D19: ℃
B20: ※ 고정변수는 20런 전체와 두 파팅면 모두 동일하게 유지. 값은 실험 담당자 지정(파란색).
B22: 3. 반응변수 (캐비티/시편 단위 측정)
B23: 반응변수 | C23: 단위 / 형식 | D23: 측정 단위 | E23: 유형 | F23: 비고
B24: 표면함침율 (핵심) | C24: % (P1, P2, P3) | D24: 캐비티당 3포인트 | E24: 연속형 | F24: P1–P3 측정 위치를 도면에 고정해 두고 모든 시편에서 동일 위치 측정. 분석은 3점 평균과 함께 3점 범위(불균일도)도 검토
B25: 인장강도 | C25: MPa | D25: 시편 1개/캐비티 | E25: 연속형 | F25: 시편 채취 위치 고정
B26: 버 발생 여부 | C26: 발생 1 / 미발생 0 | D26: 캐비티 | E26: 이진형 | F26: 반복 샷이 있으면 발생률(0–1)로 요약
B27: 코흘림 여부 | C27: 발생 1 / 미발생 0 | D27: 캐비티 (노즐/게이트) | E27: 이진형 | F27: 반복 샷이 있으면 발생률(0–1)로 요약
B28: 무게 | C28: g | D28: 캐비티 | E28: 연속형 | F28: 함침율·충전 상태의 보조 지표
B30: 4. 설계 구성
B31: 구성 | C31: 조건 | D31: 런 수 | E31: 측정 파팅면 | F31: 목적 / 추정 가능 효과
B32: ① 주 설계 | C32: 핫러너 온도 4수준 × 사출속도 4수준, 금형온도 60℃ | D32: 16 | E32: 고정측 | F32: 4×4 완전요인. 핫러너 온도(3 df)·사출속도(3 df) 주효과 + 교호작용(9 df). 무반복이므로 회귀모형(1·2차항 + 교호작용)으로 적합하고 나머지를 오차로 사용
B33: ② 추가 실험 | C33: 핫러너 온도 4수준, 금형온도 40℃, 사출속도 80 mm/s | D33: 4 | E33: 고정측 | F33: 같은 온도·속도의 60℃ 런과 짝 비교 → 금형온도 효과(1 df)와 금형온도×핫러너 온도 교호작용(3 df)을 속도 80 mm/s 조건에서 추정. 짝: 210℃→표준 17↔4, 223℃→표준 18↔8, 237℃→표준 19↔12, 250℃→표준 20↔16
B34: ③ 이동측 2² | C34: 핫러너 온도 210/250 × 사출속도 20/80, 금형온도 60℃ | D34: 4 | E34: 이동측 (①의 꼭짓점 런에서 추가 측정) | F34: 이동측 주효과 2개 + 교호작용 1개(3 df, 오차 df 0 → 반복 샷 부표본 또는 교호작용 풀링). 같은 런의 고정측과 파팅면 간 차이 비교
B35: 합계 | C35: 사출조건 20개 | D35: 20 런 / 24 시편 | E35: 고정측 20 + 이동측 4 | F35: 이동측 조건이 모두 고정측 런에 내포 → 추가 성형 런 0
B37: 5. 실험 노력 비교 (샷 1회 기준; 반복 샷 수만큼 비례)
B38: 항목 | C38: 양측 모두 20런 측정 (비교 기준) | D38: 본 설계 | E38: 절감 | F38: 산출 근거
B39: 사출조건 설정 횟수 (런 수) | C39: 20 | D39: 20 | E39: =IF(C39=0,"",1-D39/C39) -> 0 | F39: 이동측 조건이 고정측 런에 내포되어 추가 런 없음
B40: 측정 시편 수 (캐비티 × 런) | C40: 40 | D40: 24 | E40: =IF(C40=0,"",1-D40/C40) -> 0.4 | F40: 고정측 20 + 이동측 4
B41: 표면함침율 측정 포인트 수 | C41: 120 | D41: 72 | E41: =IF(C41=0,"",1-D41/C41) -> 0.4 | F41: 시편 수 × 3포인트
B42: 인장시험 시편 수 | C42: 40 | D42: 24 | E42: =IF(C42=0,"",1-D42/C42) -> 0.4 | F42: 시편당 1개
B43: ※ 파란색 숫자는 설계에서 산출한 입력값, 절감률은 수식. 비교 기준 = 고정측 20런 + 이동측 20런을 각각 측정하는 경우.
B45: 6. 실행순서 및 분석 시 유의사항
B46: 1) 실행순서: 주 설계 16런(금형온도 60℃)을 먼저 수행 — 핫러너 온도 오름차순 4블록(210→223→237→250, 승온·안정화 시간 절약), 블록 내 사출속도 순서는 무작위(난수 seed = 20260914). 이어서 금형온도를 40℃로 내리고 추가 4런을 핫러너 온도 내림차순(250→237→223→210)으로 수행한다(마지막 블록이 250℃이므로 온도 변경 1회 절약). 금형온도 변경 1회, 핫러너 온도 변경 6회. 표준순서 열을 함께 두었다.
B47: 2) 핫러너 온도·금형온도는 완전 무작위화되지 않은 제한 무작위화(분할구, split-plot) 구조이며, 추가 4런은 모두 실험 후반에 몰려 있어 금형온도 효과가 시간 추세(재료 로트·기계 상태 변화)와 혼입될 수 있다. 각 온도 블록 시작 시와 금형온도 변경 후에는 퍼지 샷으로 안정화를 확인한 뒤 시편을 채취하고, 가능하면 추가 4런은 주 설계와 같은 날·같은 재료 로트로 진행한다.
...

Sheet 실험계획표
A1: 자동차 복합재 부품 텐덤금형 사출실험 계획표 — 실행순서 기준 (고정측 20런 / 이동측 4런 내포)
A2: 매 런 두 파팅면(고정측 1캐비티, 이동측 1캐비티) 동일 조건으로 성형. 노란색 행(이동측 측정 = O, M1–M4)은 이동측 시편도 측정. 보라색 행은 금형온도 40℃ 추가 런. 연노랑 셀은 실험 중 기록.
A3: 고정 조건(전 런 동일): 보압 최고사출압의 100% · 보압시간 6 s · 계량거리 86 mm · V/P 전환 36 mm · 냉각시간 60 s · 배럴온도 210 ℃ · 노즐온도 215 ℃
A5: 실행 순서 | B5: 표준 순서 | C5: 블록 (핫러너) | D5: 구분 | E5: 핫러너 온도 (℃) | F5: 금형온도 (℃) | G5: 사출속도 (mm/s) | H5: A 코드 | I5: B 코드 | J5: C 코드 | K5: 고정측 캐비티 측정 | L5: 이동측 캐비티 측정 | M5: 이동측 런번호 | N5: 실시 일시 | O5: 샷 카운터 (시작–끝) | P5: 비고
A6: 1 | B6: 1 | C6: 1 | D6: 주 설계 | E6: 210 | F6: 60 | G6: 20 | H6: -1 | I6: 1 | J6: -1 | K6: O | L6: O | M6: M1 | P6: 이동측 2² 꼭짓점 M1
A7: 2 | B7: 2 | C7: 1 | D7: 주 설계 | E7: 210 | F7: 60 | G7: 40 | H7: -1 | I7: 1 | J7: -0.3333 | K7: O | L7: – | M7: –
A8: 3 | B8: 3 | C8: 1 | D8: 주 설계 | E8: 210 | F8: 60 | G8: 60 | H8: -1 | I8: 1 | J8: 0.3333 | K8: O | L8: – | M8: –
A9: 4 | B9: 4 | C9: 1 | D9: 주 설계 | E9: 210 | F9: 60 | G9: 80 | H9: -1 | I9: 1 | J9: 1 | K9: O | L9: O | M9: M3 | P9: 이동측 2² 꼭짓점 M3
A10: 5 | B10: 6 | C10: 2 | D10: 주 설계 | E10: 223 | F10: 60 | G10: 40 | H10: -0.3333 | I10: 1 | J10: -0.3333 | K10: O | L10: – | M10: –
A11: 6 | B11: 5 | C11: 2 | D11: 주 설계 | E11: 223 | F11: 60 | G11: 20 | H11: -0.3333 | I11: 1 | J11: -1 | K11: O | L11: – | M11: –
A12: 7 | B12: 8 | C12: 2 | D12: 주 설계 | E12: 223 | F12: 60 | G12: 80 | H12: -0.3333 | I12: 1 | J12: 1 | K12: O | L12: – | M12: –
A13: 8 | B13: 7 | C13: 2 | D13: 주 설계 | E13: 223 | F13: 60 | G13: 60 | H13: -0.3333 | I13: 1 | J13: 0.3333 | K13: O | L13: – | M13: –
A14: 9 | B14: 9 | C14: 3 | D14: 주 설계 | E14: 237 | F14: 60 | G14: 20 | H14: 0.3333 | I14: 1 | J14: -1 | K14: O | L14: – | M14: –
A15: 10 | B15: 10 | C15: 3 | D15: 주 설계 | E15: 237 | F15: 60 | G15: 40 | H15: 0.3333 | I15: 1 | J15: -0.3333 | K15: O | L15: – | M15: –
A16: 11 | B16: 12 | C16: 3 | D16: 주 설계 | E16: 237 | F16: 60 | G16: 80 | H16: 0.3333 | I16: 1 | J16: 1 | K16: O | L16: – | M16: –
A17: 12 | B17: 11 | C17: 3 | D17: 주 설계 | E17: 237 | F17: 60 | G17: 60 | H17: 0.3333 | I17: 1 | J17: 0.3333 | K17: O | L17: – | M17: –
A18: 13 | B18: 13 | C18: 4 | D18: 주 설계 | E18: 250 | F18: 60 | G18: 20 | H18: 1 | I18: 1 | J18: -1 | K18: O | L18: O | M18: M2 | P18: 이동측 2² 꼭짓점 M2
A19: 14 | B19: 16 | C19: 4 | D19: 주 설계 | E19: 250 | F19: 60 | G19: 80 | H19: 1 | I19: 1 | J19: 1 | K19: O | L19: O | M19: M4 | P19: 이동측 2² 꼭짓점 M4
A20: 15 | B20: 15 | C20: 4 | D20: 주 설계 | E20: 250 | F20: 60 | G20: 60 | H20: 1 | I20: 1 | J20: 0.3333 | K20: O | L20: – | M20: –
A21: 16 | B21: 14 | C21: 4 | D21: 주 설계 | E21: 250 | F21: 60 | G21: 40 | H21: 1 | I21: 1 | J21: -0.3333 | K21: O | L21: – | M21: –
A22: 17 | B22: 20 | C22: 4 | D22: 추가 (40℃) | E22: 250 | F22: 40 | G22: 80 | H22: 1 | I22: -1 | J22: 1 | K22: O | L22: – | M22: – | P22: 40℃ 추가 런 · 짝 = 실행순서 14 · 선택: 이동측 측정
A23: 18 | B23: 19 | C23: 3 | D23: 추가 (40℃) | E23: 237 | F23: 40 | G23: 80 | H23: 0.3333 | I23: -1 | J23: 1 | K23: O | L23: – | M23: – | P23: 40℃ 추가 런 · 짝 = 실행순서 11
A24: 19 | B24: 18 | C24: 2 | D24: 추가 (40℃) | E24: 223 | F24: 40 | G24: 80 | H24: -0.3333 | I24: -1 | J24: 1 | K24: O | L24: – | M24: – | P24: 40℃ 추가 런 · 짝 = 실행순서 7
A25: 20 | B25: 17 | C25: 1 | D25: 추가 (40℃) | E25: 210 | F25: 40 | G25: 80 | H25: -1 | I25: -1 | J25: 1 | K25: O | L25: – | M25: – | P25: 40℃ 추가 런 · 짝 = 실행순서 4 · 선택: 이동측 측정
A27: 고정측 측정 런 수 | E27: =COUNTIF(K6:K25,"O") -> 20
A28: 이동측 측정 런 수 | E28: =COUNTIF(L6:L25,"O") -> 4
A29: 금형온도 40℃ 런 수 | E29: =COUNTIF(F6:F25,40) -> 4
A30: 총 측정 시편 수 (샷 1회 기준) | E30: =E27+E28 -> 24
A32: 범례: 파란/녹색/주황/회색 배경 = 핫러너 온도 블록 1/2/3/4(60℃ 주 설계, 실행순서 1–16), 보라 = 금형온도 40℃ 추가 런(실행순서 17–20, 온도 내림차순), 노랑 = 이동측 측정 런(2² 꼭짓점), 연노랑 셀 = 실험 중 기록 입력. 실행순서 난수 seed 20260914.

Sheet 이동측 2² 설계
A1: 이동측 캐비티 2² 완전요인 설계 — 고정측 주 설계(60℃)에 내포된 4개 꼭짓점 런
A2: 인자: 핫러너 온도(210/250℃), 사출속도(20/80 mm/s). 금형온도 60℃ 고정. 아래 4런은 모두 실험계획표의 런과 동일 조건이며, 해당 런에서 이동측 시편을 추가 측정한다.
A4: 이동측 런번호 | B4: 대응 실행순서 | C4: 대응 표준순서 | D4: 핫러너 온도 (℃) | E4: 금형온도 (℃) | F4: 사출속도 (mm/s) | G4: A 코드 | H4: C 코드 | I4: 핫러너 블록 | J4: 비고
A5: M1 | B5: 1 | C5: 1 | D5: 210 | E5: 60 | F5: 20 | G5: -1 | H5: -1 | I5: 1 | J5: 2² 표준순서(Yates) 1
A6: M2 | B6: 13 | C6: 13 | D6: 250 | E6: 60 | F6: 20 | G6: 1 | H6: -1 | I6: 4 | J6: 2² 표준순서(Yates) 2
A7: M3 | B7: 4 | C7: 4 | D7: 210 | E7: 60 | F7: 80 | G7: -1 | H7: 1 | I7: 1 | J7: 2² 표준순서(Yates) 3
A8: M4 | B8: 14 | C8: 16 | D8: 250 | E8: 60 | F8: 80 | G8: 1 | H8: 1 | I8: 4 | J8: 2² 표준순서(Yates) 4
A10: 균형 확인 (각 수준 2런)
A11: 핫러너 온도 | B11: 210 | C11: =COUNTIF(D5:D8,B11) -> 2 | D11: 250 | E11: =COUNTIF(D5:D8,D11) -> 2
A12: 사출속도 | B12: 20 | C12: =COUNTIF(F5:F8,B12) -> 2 | D12: 80 | E12: =COUNTIF(F5:F8,D12) -> 2
A14: 선택 추가 측정 (금형온도 영향 확인용, 40℃ 런)
A15: 구분 | B15: 대응 실행순서 | C15: 대응 표준순서 | D15: 핫러너 온도 (℃) | E15: 금형온도 (℃) | F15: 사출속도 (mm/s) | G15: A 코드 | H15: C 코드 | I15: 핫러너 블록 | J15: 비고
A16: 옵션 1 | B16: 17 | C16: 20 | D16: 250 | E16: 40 | F16: 80 | G16: 1 | H16: 1 | I16: 4 | J16: 60℃ 런 M4(같은 온도·속도)과 비교
A17: 옵션 2 | B17: 20 | C17: 17 | D17: 210 | E17: 40 | F17: 80 | G17: -1 | H17: 1 | I17: 1 | J17: 60℃ 런 M3(같은 온도·속도)과 비교
A19: 추정 가능 효과: A(핫러너 온도), C(사출속도) 주효과와 AC 교호작용 (3 자유도, 오차 자유도 0). 반복 샷을 부표본으로 두고 혼합모형으로 분석하거나, 교호작용을 오차로 풀링해 주효과만 검정. 선택 측정 2런을 더하면 금형온도 40 vs 60 비교(속도 80)가 추가된다.

Sheet 데이터 기록표
A1: 데이터 기록표 — 런 × 파팅면 × 샷 (조건당 3샷 기준)
A2: 노란색 셀에 측정값 입력: 표면함침율 P1–P3(%), 인장강도(MPa), 버 발생·코흘림(발생 1 / 미발생 0), 무게(g). 함침율 평균·범위는 수식. "예시" 행은 입력 형식 참고용(집계에서 제외)이며, 샷 수가 다르면 행을 추가/삭제한다. 선택 측정(40℃ 런 이동측)을 하면 해당 런 아래에 이동측 행을 추가한다.
A4: 실행 순서 | B4: 파팅면 | C4: 샷 | D4: 핫러너 온도 (℃) | E4: 금형온도 (℃) | F4: 사출속도 (mm/s) | G4: 함침율 P1 (%) | H4: 함침율 P2 (%) | I4: 함침율 P3 (%) | J4: 함침율 평균 (%) | K4: 함침율 범위 (%p) | L4: 인장강도 (MPa) | M4: 버 발생 (1/0) | N4: 코흘림 (1/0) | O4: 무게 (g) | P4: 비고
A5: 예시 | B5: 고정측 | C5: 1 | D5: 210 | E5: 60 | F5: 20 | G5: 93.2 | H5: 91.8 | I5: 94.5 | J5: =IF(COUNT(G5:I5)=0,"",AVERAGE(G5:I5)) -> 93.166667 | K5: =IF(COUNT(G5:I5)<2,"",MAX(G5:I5)-MIN(G5:I5)) -> 2.7 | L5: 85.3 | M5: 0 | N5: 1 | O5: 152.4
A6: ↓ 실제 기록
A7: 1 | B7: 고정측 | C7: 943 | D7: 210 | E7: 60 | F7: 20 | G7: 95.558167 | H7: 87.513733 | I7: 75.819397 | J7: =IF(COUNT(G7:I7)=0,"",AVERAGE(G7:I7)) -> 86.297099 | K7: =IF(COUNT(G7:I7)<2,"",MAX(G7:I7)-MIN(G7:I7)) -> 19.73877 | M7: 0 | N7: 0 | O7: 76.4 | P7: 보압 55
A8: 1 | B8: 고정측 | C8: 945 | D8: 210 | E8: 60 | F8: 20 | G8: 98.002625 | H8: 94.842529 | I8: 67.765808 | J8: =IF(COUNT(G8:I8)=0,"",AVERAGE(G8:I8)) -> 86.870321 | K8: =IF(COUNT(G8:I8)<2,"",MAX(G8:I8)-MIN(G8:I8)) -> 30.236816 | M8: 0 | N8: 0 | O8: 76.45
A9: 1 | B9: 고정측 | C9: 947 | D9: 210 | E9: 60 | F9: 20 | G9: 99.482727 | H9: 95.903015 | I9: 87.239075 | J9: =IF(COUNT(G9:I9)=0,"",AVERAGE(G9:I9)) -> 94.208272 | K9: =IF(COUNT(G9:I9)<2,"",MAX(G9:I9)-MIN(G9:I9)) -> 12.243652 | M9: 0 | N9: 0 | O9: 76.5
A10: 1 | B10: 이동측 | C10: 954 | D10: 210 | E10: 60 | F10: 20 | G10: 62.359619 | H10: 91.014099 | I10: 96.685791 | J10: =IF(COUNT(G10:I10)=0,"",AVERAGE(G10:I10)) -> 83.35317 | K10: =IF(COUNT(G10:I10)<2,"",MAX(G10:I10)-MIN(G10:I10)) -> 34.326172 | M10: 0 | N10: 0 | O10: 76.38
A11: 1 | B11: 이동측 | C11: 956 | D11: 210 | E11: 60 | F11: 20 | G11: 96.737671 | H11: 94.406128 | I11: 60.362244 | J11: =IF(COUNT(G11:I11)=0,"",AVERAGE(G11:I11)) -> 83.835347 | K11: =IF(COUNT(G11:I11)<2,"",MAX(G11:I11)-MIN(G11:I11)) -> 36.375427 | M11: 0 | N11: 0 | O11: 76.41
A12: 1 | B12: 이동측 | C12: 958 | D12: 210 | E12: 60 | F12: 20 | G12: 73.071289 | H12: 97.53418 | I12: 97.361755 | J12: =IF(COUNT(G12:I12)=0,"",AVERAGE(G12:I12)) -> 89.322408 | K12: =IF(COUNT(G12:I12)<2,"",MAX(G12:I12)-MIN(G12:I12)) -> 24.462891 | M12: 0 | N12: 0 | O12: 76.39
A13: 2 | B13: 고정측 | C13: 965 | D13: 210 | E13: 60 | F13: 40 | G13: 98.370361 | H13: 96.647644 | I13: 64.607239 | J13: =IF(COUNT(G13:I13)=0,"",AVERAGE(G13:I13)) -> 86.541748 | K13: =IF(COUNT(G13:I13)<2,"",MAX(G13:I13)-MIN(G13:I13)) -> 33.763123 | M13: 0 | N13: 0 | O13: 77.55 | P13: 보압 70
A14: 2 | B14: 고정측 | C14: 967 | D14: 210 | E14: 60 | F14: 40 | G14: 99.032593 | H14: 96.640015 | I14: 64.624023 | J14: =IF(COUNT(G14:I14)=0,"",AVERAGE(G14:I14)) -> 86.765544 | K14: =IF(COUNT(G14:I14)<2,"",MAX(G14:I14)-MIN(G14:I14)) -> 34.408569 | M14: 0 | N14: 0 | O14: 77.6
A15: 2 | B15: 고정측 | C15: 969 | D15: 210 | E15: 60 | F15: 40 | G15: 93.489075 | H15: 95.66803 | I15: 90.550232 | J15: =IF(COUNT(G15:I15)=0,"",AVERAGE(G15:I15)) -> 93.235779 | K15: =IF(COUNT(G15:I15)<2,"",MAX(G15:I15)-MIN(G15:I15)) -> 5.1177979 | M15: 0 | N15: 0 | O15: 77.52
A16: 3 | B16: 고정측 | C16: 975 | D16: 210 | E16: 60 | F16: 60 | G16: 96.096802 | H16: 96.783447 | I16: 91.969299 | J16: =IF(COUNT(G16:I16)=0,"",AVERAGE(G16:I16)) -> 94.949849 | K16: =IF(COUNT(G16:I16)<2,"",MAX(G16:I16)-MIN(G16:I16)) -> 4.8141479 | M16: 0 | N16: 0 | O16: 79.09 | P16: 보압 85
A17: 3 | B17: 고정측 | C17: 977 | D17: 210 | E17: 60 | F17: 60 | G17: 98.027039 | H17: 96.630859 | I17: 95.26062 | J17: =IF(COUNT(G17:I17)=0,"",AVERAGE(G17:I17)) -> 96.639506 | K17: =IF(COUNT(G17:I17)<2,"",MAX(G17:I17)-MIN(G17:I17)) -> 2.7664185 | M17: 0 | N17: 0 | O17: 79.46
A18: 3 | B18: 고정측 | C18: 979 | D18: 210 | E18: 60 | F18: 60 | G18: 97.65625 | H18: 96.620178 | I18: 96.794128 | J18: =IF(COUNT(G18:I18)=0,"",AVERAGE(G18:I18)) -> 97.023519 | K18: =IF(COUNT(G18:I18)<2,"",MAX(G18:I18)-MIN(G18:I18)) -> 1.0360718 | M18: 0 | N18: 0 | O18: 79.25
A19: 4 | B19: 고정측 | C19: 991 | D19: 210 | E19: 60 | F19: 80 | G19: 96.513367 | H19: 96.292114 | I19: 97.314453 | J19: =IF(COUNT(G19:I19)=0,"",AVERAGE(G19:I19)) -> 96.706645 | K19: =IF(COUNT(G19:I19)<2,"",MAX(G19:I19)-MIN(G19:I19)) -> 1.0223389 | M19: 1 | N19: 0 | O19: 82.13 | P19: 보압 95
A20: 4 | B20: 고정측 | C20: 993 | D20: 210 | E20: 60 | F20: 80 | G20: 97.492981 | H20: 96.456909 | I20: 96.220398 | J20: =IF(COUNT(G20:I20)=0,"",AVERAGE(G20:I20)) -> 96.723429 | K20: =IF(COUNT(G20:I20)<2,"",MAX(G20:I20)-MIN(G20:I20)) -> 1.272583 | M20: 1 | N20: 0 | O20: 82.59
A21: 4 | B21: 고정측 | C21: 995 | D21: 210 | E21: 60 | F21: 80 | G21: 96.16394 | H21: 95.962524 | I21: 96.109009 | J21: =IF(COUNT(G21:I21)=0,"",AVERAGE(G21:I21)) -> 96.078491 | K21: =IF(COUNT(G21:I21)<2,"",MAX(G21:I21)-MIN(G21:I21)) -> 0.20141602 | M21: 1 | N21: 0 | O21: 82.5
A22: 4 | B22: 이동측 | C22: 1000 | D22: 210 | E22: 60 | F22: 80 | G22: 90.533447 | H22: 98.936462 | I22: 97.589111 | J22: =IF(COUNT(G22:I22)=0,"",AVERAGE(G22:I22)) -> 95.68634 | K22: =IF(COUNT(G22:I22)<2,"",MAX(G22:I22)-MIN(G22:I22)) -> 8.4030151 | M22: 1 | N22: 0 | O22: 81.96
A23: 4 | B23: 이동측 | C23: 1002 | D23: 210 | E23: 60 | F23: 80 | G23: 97.174072 | H23: 96.144104 | I23: 95.291138 | J23: =IF(COUNT(G23:I23)=0,"",AVERAGE(G23:I23)) -> 96.203105 | K23: =IF(COUNT(G23:I23)<2,"",MAX(G23:I23)-MIN(G23:I23)) -> 1.8829346 | M23: 1 | N23: 0 | O23: 81.96
A24: 4 | B24: 이동측 | C24: 1004 | D24: 210 | E24: 60 | F24: 80 | G24: 96.943665 | H24: 96.310425 | I24: 95.974731 | J24: =IF(COUNT(G24:I24)=0,"",AVERAGE(G24:I24)) -> 96.409607 | K24: =IF(COUNT(G24:I24)<2,"",MAX(G24:I24)-MIN(G24:I24)) -> 0.96893311 | M24: 1 | N24: 0 | O24: 81.82
A25: 5 | B25: 고정측 | C25: 1017 | D25: 223 | E25: 60 | F25: 40 | G25: 98.014832 | H25: 96.638489 | I25: 87.005615 | J25: =IF(COUNT(G25:I25)=0,"",AVERAGE(G25:I25)) -> 93.886312 | K25: =IF(COUNT(G25:I25)<2,"",MAX(G25:I25)-MIN(G25:I25)) -> 11.009216 | M25: 0 | N25: 0 | O25: 76.9 | P25: 보압 60
A26: 5 | B26: 고정측 | C26: 1019 | D26: 223 | E26: 60 | F26: 40 | G26: 97.631836 | H26: 95.330811 | I26: 91.226196 | J26: =IF(COUNT(G26:I26)=0,"",AVERAGE(G26:I26)) -> 94.729614 | K26: =IF(COUNT(G26:I26)<2,"",MAX(G26:I26)-MIN(G26:I26)) -> 6.4056396 | M26: 0 | N26: 0 | O26: 76.81
A27: 5 | B27: 고정측 | C27: 1021 | D27: 223 | E27: 60 | F27: 40 | G27: 99.000549 | H27: 96.614075 | I27: 73.762512 | J27: =IF(COUNT(G27:I27)=0,"",AVERAGE(G27:I27)) -> 89.792379 | K27: =IF(COUNT(G27:I27)<2,"",MAX(G27:I27)-MIN(G27:I27)) -> 25.238037 | M27: 0 | N27: 0 | O27: 76.83
A28: 6 | B28: 고정측 | C28: 1027 | D28: 223 | E28: 60 | F28: 20 | G28: 96.569824 | H28: 92.596436 | I28: 85.168457 | J28: =IF(COUNT(G28:I28)=0,"",AVERAGE(G28:I28)) -> 91.444906 | K28: =IF(COUNT(G28:I28)<2,"",MAX(G28:I28)-MIN(G28:I28)) -> 11.401367 | M28: 0 | N28: 0 | O28: 76.2 | P28: 보압 50
A29: 6 | B29: 고정측 | C29: 1029 | D29: 223 | E29: 60 | F29: 20 | G29: 97.52655 | H29: 96.058655 | I29: 57.647705 | J29: =IF(COUNT(G29:I29)=0,"",AVERAGE(G29:I29)) -> 83.744303 | K29: =IF(COUNT(G29:I29)<2,"",MAX(G29:I29)-MIN(G29:I29)) -> 39.878845 | M29: 0 | N29: 0 | O29: 76.25
A30: 6 | B30: 고정측 | C30: 1031 | D30: 223 | E30: 60 | F30: 20 | G30: 95.903015 | H30: 94.845581 | I30: 69.512939 | J30: =IF(COUNT(G30:I30)=0,"",AVERAGE(G30:I30)) -> 86.753845 | K30: =IF(COUNT(G30:I30)<2,"",MAX(G30:I30)-MIN(G30:I30)) -> 26.390076 | M30: 0 | N30: 0 | O30: 76.27
A31: 7 | B31: 고정측 | C31: 1037 | D31: 223 | E31: 60 | F31: 80 | G31: 96.788025 | H31: 97.201538 | I31: 94.129944 | J31: =IF(COUNT(G31:I31)=0,"",AVERAGE(G31:I31)) -> 96.039836 | K31: =IF(COUNT(G31:I31)<2,"",MAX(G31:I31)-MIN(G31:I31)) -> 3.0715942 | M31: 0 | N31: 0 | O31: 78.48 | P31: 보압 80
A32: 7 | B32: 고정측 | C32: 1039 | D32: 223 | E32: 60 | F32: 80 | G32: 97.190857 | H32: 96.891785 | I32: 93.261719 | J32: =IF(COUNT(G32:I32)=0,"",AVERAGE(G32:I32)) -> 95.781453 | K32: =IF(COUNT(G32:I32)<2,"",MAX(G32:I32)-MIN(G32:I32)) -> 3.9291382 | M32: 0 | N32: 0 | O32: 78.38
A33: 7 | B33: 고정측 | C33: 1041 | D33: 223 | E33: 60 | F33: 80 | G33: 95.707703 | H33: 96.330261 | I33: 95.793152 | J33: =IF(COUNT(G33:I33)=0,"",AVERAGE(G33:I33)) -> 95.943705 | K33: =IF(COUNT(G33:I33)<2,"",MAX(G33:I33)-MIN(G33:I33)) -> 0.62255859 | M33: 0 | N33: 0 | O33: 79.06
A34: 8 | B34: 고정측 | C34: 1051 | D34: 223 | E34: 60 | F34: 60 | G34: 96.458435 | H34: 96.243286 | I34: 95.646667 | J34: =IF(COUNT(G34:I34)=0,"",AVERAGE(G34:I34)) -> 96.11613 | K34: =IF(COUNT(G34:I34)<2,"",MAX(G34:I34)-MIN(G34:I34)) -> 0.81176758 | M34: 0 | N34: 0 | O34: 77.29 | P34: 보압 70
A35: 8 | B35: 고정측 | C35: 1053 | D35: 223 | E35: 60 | F35: 60 | G35: 96.147156 | H35: 97.224426 | I35: 96.995544 | J35: =IF(COUNT(G35:I35)=0,"",AVERAGE(G35:I35)) -> 96.789042 | K35: =IF(COUNT(G35:I35)<2,"",MAX(G35:I35)-MIN(G35:I35)) -> 1.0772705 | M35: 0 | N35: 0 | O35: 77.34
A36: 8 | B36: 고정측 | C36: 1055 | D36: 223 | E36: 60 | F36: 60 | G36: 95.472717 | H36: 98.08197 | I36: 96.710205 | J36: =IF(COUNT(G36:I36)=0,"",AVERAGE(G36:I36)) -> 96.754964 | K36: =IF(COUNT(G36:I36)<2,"",MAX(G36:I36)-MIN(G36:I36)) -> 2.6092529 | M36: 0 | N36: 0 | O36: 77.3
A37: 9 | B37: 고정측 | C37: 1063 | D37: 237 | E37: 60 | F37: 20 | G37: 97.003174 | H37: 88.470459 | I37: 89.857483 | J37: =IF(COUNT(G37:I37)=0,"",AVERAGE(G37:I37)) -> 91.777039 | K37: =IF(COUNT(G37:I37)<2,"",MAX(G37:I37)-MIN(G37:I37)) -> 8.5327148 | M37: 0 | N37: 0 | O37: 75.53 | P37: 보압 40
A38: 9 | B38: 고정측 | C38: 1065 | D38: 237 | E38: 60 | F38: 20 | G38: 95.025635 | H38: 93.331909 | I38: 71.188354 | J38: =IF(COUNT(G38:I38)=0,"",AVERAGE(G38:I38)) -> 86.515299 | K38: =IF(COUNT(G38:I38)<2,"",MAX(G38:I38)-MIN(G38:I38)) -> 23.83728 | M38: 0 | N38: 0 | O38: 75.43
A39: 9 | B39: 고정측 | C39: 1067 | D39: 237 | E39: 60 | F39: 20 | G39: 95.732117 | H39: 95.452881 | I39: 90.116882 | J39: =IF(COUNT(G39:I39)=0,"",AVERAGE(G39:I39)) -> 93.767293 | K39: =IF(COUNT(G39:I39)<2,"",MAX(G39:I39)-MIN(G39:I39)) -> 5.6152344 | M39: 0 | N39: 0 | O39: 75.53
A40: 10 | B40: 고정측 | C40: 1073 | D40: 237 | E40: 60 | F40: 40 | G40: 98.454285 | H40: 97.996521 | I40: 93.652344 | J40: =IF(COUNT(G40:I40)=0,"",AVERAGE(G40:I40)) -> 96.70105 | K40: =IF(COUNT(G40:I40)<2,"",MAX(G40:I40)-MIN(G40:I40)) -> 4.8019409 | M40: 0 | N40: 0 | O40: 76.08 | P40: 보압 55
A41: 10 | B41: 고정측 | C41: 1075 | D41: 237 | E41: 60 | F41: 40 | G41: 96.710205 | H41: 96.432495 | I41: 96.876526 | J41: =IF(COUNT(G41:I41)=0,"",AVERAGE(G41:I41)) -> 96.673075 | K41: =IF(COUNT(G41:I41)<2,"",MAX(G41:I41)-MIN(G41:I41)) -> 0.44403076 | M41: 0 | N41: 0 | O41: 76.02
...

Sheet 분석용 요약
A1: 분석용 요약 — 런 × 파팅면 (반복 샷 평균, 데이터 기록표에서 자동 집계)
A2: 행 1개 = 런 1개 × 파팅면 1개 (고정측 20행 + 이동측 4행 = 24행). 이진 반응은 발생률(0–1). 통계 소프트웨어에는 A~K열(설계)과 M~R열(반응)을 그대로 복사해 사용. 파팅면 차이 열은 이동측 측정 런에서만 계산.
A4: 실행 순서 | B4: 표준 순서 | C4: 파팅면 | D4: 설계 역할 | E4: 핫러너 온도 (℃) | F4: 금형온도 (℃) | G4: 사출속도 (mm/s) | H4: A 코드 | I4: B 코드 | J4: C 코드 | K4: 블록 | L4: 샷 수 (함침율 입력) | M4: 함침율 평균 (%) | N4: 함침율 3점 범위 평균 (%p) | O4: 인장강도 평균 (MPa) | P4: 버 발생률 | Q4: 코흘림 발생률 | R4: 무게 평균 (g) | S4: 파팅면 차이 함침율 (%p) | T4: 파팅면 차이 인장강도 (MPa) | U4: 파팅면 차이 무게 (g)
A5: 1 | B5: 1 | C5: 고정측 | D5: 4×4 + 2² 꼭짓점 | E5: 210 | F5: 60 | G5: 20 | H5: -1 | I5: 1 | J5: -1 | K5: 1 | L5: =COUNTIFS('데이터 기록표'!$A$7:$A$78,$A5,'데이터 기록표'!$B$7:$B$78,$C5,'데이터 기록표'!$G$7:$G$78,"<>") -> 3 | M5: =IFERROR(AVERAGEIFS('데이터 기록표'!$J$7:$J$78,'데이터 기록표'!$A$7:$A$78,$A5,'데이터 기록표'!$B$7:$B$78,$C5),"") -> 89.125231 | N5: =IFERROR(AVERAGEIFS('데이터 기록표'!$K$7:$K$78,'데이터 기록표'!$A$7:$A$78,$A5,'데이터 기록표'!$B$7:$B$78,$C5),"") -> 20.739746 | O5: =IFERROR(AVERAGEIFS('데이터 기록표'!$L$7:$L$78,'데이터 기록표'!$A$7:$A$78,$A5,'데이터 기록표'!$B$7:$B$78,$C5),"") | P5: =IFERROR(AVERAGEIFS('데이터 기록표'!$M$7:$M$78,'데이터 기록표'!$A$7:$A$78,$A5,'데이터 기록표'!$B$7:$B$78,$C5),"") -> 0 | Q5: =IFERROR(AVERAGEIFS('데이터 기록표'!$N$7:$N$78,'데이터 기록표'!$A$7:$A$78,$A5,'데이터 기록표'!$B$7:$B$78,$C5),"") -> 0 | R5: =IFERROR(AVERAGEIFS('데이터 기록표'!$O$7:$O$78,'데이터 기록표'!$A$7:$A$78,$A5,'데이터 기록표'!$B$7:$B$78,$C5),"") -> 76.45
A6: 1 | B6: 1 | C6: 이동측 | D6: 2² M1 | E6: 210 | F6: 60 | G6: 20 | H6: -1 | I6: 1 | J6: -1 | K6: 1 | L6: =COUNTIFS('데이터 기록표'!$A$7:$A$78,$A6,'데이터 기록표'!$B$7:$B$78,$C6,'데이터 기록표'!$G$7:$G$78,"<>") -> 3 | M6: =IFERROR(AVERAGEIFS('데이터 기록표'!$J$7:$J$78,'데이터 기록표'!$A$7:$A$78,$A6,'데이터 기록표'!$B$7:$B$78,$C6),"") -> 85.503642 | N6: =IFERROR(AVERAGEIFS('데이터 기록표'!$K$7:$K$78,'데이터 기록표'!$A$7:$A$78,$A6,'데이터 기록표'!$B$7:$B$78,$C6),"") -> 31.721497 | O6: =IFERROR(AVERAGEIFS('데이터 기록표'!$L$7:$L$78,'데이터 기록표'!$A$7:$A$78,$A6,'데이터 기록표'!$B$7:$B$78,$C6),"") | P6: =IFERROR(AVERAGEIFS('데이터 기록표'!$M$7:$M$78,'데이터 기록표'!$A$7:$A$78,$A6,'데이터 기록표'!$B$7:$B$78,$C6),"") -> 0 | Q6: =IFERROR(AVERAGEIFS('데이터 기록표'!$N$7:$N$78,'데이터 기록표'!$A$7:$A$78,$A6,'데이터 기록표'!$B$7:$B$78,$C6),"") -> 0 | R6: =IFERROR(AVERAGEIFS('데이터 기록표'!$O$7:$O$78,'데이터 기록표'!$A$7:$A$78,$A6,'데이터 기록표'!$B$7:$B$78,$C6),"") -> 76.393333 | S6: =IF(OR(M5="",M6=""),"",M5-M6) -> 3.6215888 | T6: =IF(OR(O5="",O6=""),"",O5-O6) | U6: =IF(OR(R5="",R6=""),"",R5-R6) -> 0.056666667
A7: 2 | B7: 2 | C7: 고정측 | D7: 4×4 | E7: 210 | F7: 60 | G7: 40 | H7: -1 | I7: 1 | J7: -0.3333 | K7: 1 | L7: =COUNTIFS('데이터 기록표'!$A$7:$A$78,$A7,'데이터 기록표'!$B$7:$B$78,$C7,'데이터 기록표'!$G$7:$G$78,"<>") -> 3 | M7: =IFERROR(AVERAGEIFS('데이터 기록표'!$J$7:$J$78,'데이터 기록표'!$A$7:$A$78,$A7,'데이터 기록표'!$B$7:$B$78,$C7),"") -> 88.84769 | N7: =IFERROR(AVERAGEIFS('데이터 기록표'!$K$7:$K$78,'데이터 기록표'!$A$7:$A$78,$A7,'데이터 기록표'!$B$7:$B$78,$C7),"") -> 24.42983 | O7: =IFERROR(AVERAGEIFS('데이터 기록표'!$L$7:$L$78,'데이터 기록표'!$A$7:$A$78,$A7,'데이터 기록표'!$B$7:$B$78,$C7),"") | P7: =IFERROR(AVERAGEIFS('데이터 기록표'!$M$7:$M$78,'데이터 기록표'!$A$7:$A$78,$A7,'데이터 기록표'!$B$7:$B$78,$C7),"") -> 0 | Q7: =IFERROR(AVERAGEIFS('데이터 기록표'!$N$7:$N$78,'데이터 기록표'!$A$7:$A$78,$A7,'데이터 기록표'!$B$7:$B$78,$C7),"") -> 0 | R7: =IFERROR(AVERAGEIFS('데이터 기록표'!$O$7:$O$78,'데이터 기록표'!$A$7:$A$78,$A7,'데이터 기록표'!$B$7:$B$78,$C7),"") -> 77.556667
A8: 3 | B8: 3 | C8: 고정측 | D8: 4×4 | E8: 210 | F8: 60 | G8: 60 | H8: -1 | I8: 1 | J8: 0.3333 | K8: 1 | L8: =COUNTIFS('데이터 기록표'!$A$7:$A$78,$A8,'데이터 기록표'!$B$7:$B$78,$C8,'데이터 기록표'!$G$7:$G$78,"<>") -> 3 | M8: =IFERROR(AVERAGEIFS('데이터 기록표'!$J$7:$J$78,'데이터 기록표'!$A$7:$A$78,$A8,'데이터 기록표'!$B$7:$B$78,$C8),"") -> 96.204291 | N8: =IFERROR(AVERAGEIFS('데이터 기록표'!$K$7:$K$78,'데이터 기록표'!$A$7:$A$78,$A8,'데이터 기록표'!$B$7:$B$78,$C8),"") -> 2.8722127 | O8: =IFERROR(AVERAGEIFS('데이터 기록표'!$L$7:$L$78,'데이터 기록표'!$A$7:$A$78,$A8,'데이터 기록표'!$B$7:$B$78,$C8),"") | P8: =IFERROR(AVERAGEIFS('데이터 기록표'!$M$7:$M$78,'데이터 기록표'!$A$7:$A$78,$A8,'데이터 기록표'!$B$7:$B$78,$C8),"") -> 0 | Q8: =IFERROR(AVERAGEIFS('데이터 기록표'!$N$7:$N$78,'데이터 기록표'!$A$7:$A$78,$A8,'데이터 기록표'!$B$7:$B$78,$C8),"") -> 0 | R8: =IFERROR(AVERAGEIFS('데이터 기록표'!$O$7:$O$78,'데이터 기록표'!$A$7:$A$78,$A8,'데이터 기록표'!$B$7:$B$78,$C8),"") -> 79.266667
A9: 4 | B9: 4 | C9: 고정측 | D9: 4×4 + 2² 꼭짓점 | E9: 210 | F9: 60 | G9: 80 | H9: -1 | I9: 1 | J9: 1 | K9: 1 | L9: =COUNTIFS('데이터 기록표'!$A$7:$A$78,$A9,'데이터 기록표'!$B$7:$B$78,$C9,'데이터 기록표'!$G$7:$G$78,"<>") -> 3 | M9: =IFERROR(AVERAGEIFS('데이터 기록표'!$J$7:$J$78,'데이터 기록표'!$A$7:$A$78,$A9,'데이터 기록표'!$B$7:$B$78,$C9),"") -> 96.502855 | N9: =IFERROR(AVERAGEIFS('데이터 기록표'!$K$7:$K$78,'데이터 기록표'!$A$7:$A$78,$A9,'데이터 기록표'!$B$7:$B$78,$C9),"") -> 0.83211263 | O9: =IFERROR(AVERAGEIFS('데이터 기록표'!$L$7:$L$78,'데이터 기록표'!$A$7:$A$78,$A9,'데이터 기록표'!$B$7:$B$78,$C9),"") | P9: =IFERROR(AVERAGEIFS('데이터 기록표'!$M$7:$M$78,'데이터 기록표'!$A$7:$A$78,$A9,'데이터 기록표'!$B$7:$B$78,$C9),"") -> 1 | Q9: =IFERROR(AVERAGEIFS('데이터 기록표'!$N$7:$N$78,'데이터 기록표'!$A$7:$A$78,$A9,'데이터 기록표'!$B$7:$B$78,$C9),"") -> 0 | R9: =IFERROR(AVERAGEIFS('데이터 기록표'!$O$7:$O$78,'데이터 기록표'!$A$7:$A$78,$A9,'데이터 기록표'!$B$7:$B$78,$C9),"") -> 82.406667
A10: 4 | B10: 4 | C10: 이동측 | D10: 2² M3 | E10: 210 | F10: 60 | G10: 80 | H10: -1 | I10: 1 | J10: 1 | K10: 1 | L10: =COUNTIFS('데이터 기록표'!$A$7:$A$78,$A10,'데이터 기록표'!$B$7:$B$78,$C10,'데이터 기록표'!$G$7:$G$78,"<>") -> 3 | M10: =IFERROR(AVERAGEIFS('데이터 기록표'!$J$7:$J$78,'데이터 기록표'!$A$7:$A$78,$A10,'데이터 기록표'!$B$7:$B$78,$C10),"") -> 96.099684 | N10: =IFERROR(AVERAGEIFS('데이터 기록표'!$K$7:$K$78,'데이터 기록표'!$A$7:$A$78,$A10,'데이터 기록표'!$B$7:$B$78,$C10),"") -> 3.7516276 | O10: =IFERROR(AVERAGEIFS('데이터 기록표'!$L$7:$L$78,'데이터 기록표'!$A$7:$A$78,$A10,'데이터 기록표'!$B$7:$B$78,$C10),"") | P10: =IFERROR(AVERAGEIFS('데이터 기록표'!$M$7:$M$78,'데이터 기록표'!$A$7:$A$78,$A10,'데이터 기록표'!$B$7:$B$78,$C10),"") -> 1 | Q10: =IFERROR(AVERAGEIFS('데이터 기록표'!$N$7:$N$78,'데이터 기록표'!$A$7:$A$78,$A10,'데이터 기록표'!$B$7:$B$78,$C10),"") -> 0 | R10: =IFERROR(AVERAGEIFS('데이터 기록표'!$O$7:$O$78,'데이터 기록표'!$A$7:$A$78,$A10,'데이터 기록표'!$B$7:$B$78,$C10),"") -> 81.913333 | S10: =IF(OR(M9="",M10=""),"",M9-M10) -> 0.40317112 | T10: =IF(OR(O9="",O10=""),"",O9-O10) | U10: =IF(OR(R9="",R10=""),"",R9-R10) -> 0.49333333
A11: 5 | B11: 6 | C11: 고정측 | D11: 4×4 | E11: 223 | F11: 60 | G11: 40 | H11: -0.3333 | I11: 1 | J11: -0.3333 | K11: 2 | L11: =COUNTIFS('데이터 기록표'!$A$7:$A$78,$A11,'데이터 기록표'!$B$7:$B$78,$C11,'데이터 기록표'!$G$7:$G$78,"<>") -> 3 | M11: =IFERROR(AVERAGEIFS('데이터 기록표'!$J$7:$J$78,'데이터 기록표'!$A$7:$A$78,$A11,'데이터 기록표'!$B$7:$B$78,$C11),"") -> 92.802768 | N11: =IFERROR(AVERAGEIFS('데이터 기록표'!$K$7:$K$78,'데이터 기록표'!$A$7:$A$78,$A11,'데이터 기록표'!$B$7:$B$78,$C11),"") -> 14.217631 | O11: =IFERROR(AVERAGEIFS('데이터 기록표'!$L$7:$L$78,'데이터 기록표'!$A$7:$A$78,$A11,'데이터 기록표'!$B$7:$B$78,$C11),"") | P11: =IFERROR(AVERAGEIFS('데이터 기록표'!$M$7:$M$78,'데이터 기록표'!$A$7:$A$78,$A11,'데이터 기록표'!$B$7:$B$78,$C11),"") -> 0 | Q11: =IFERROR(AVERAGEIFS('데이터 기록표'!$N$7:$N$78,'데이터 기록표'!$A$7:$A$78,$A11,'데이터 기록표'!$B$7:$B$78,$C11),"") -> 0 | R11: =IFERROR(AVERAGEIFS('데이터 기록표'!$O$7:$O$78,'데이터 기록표'!$A$7:$A$78,$A11,'데이터 기록표'!$B$7:$B$78,$C11),"") -> 76.846667
A12: 6 | B12: 5 | C12: 고정측 | D12: 4×4 | E12: 223 | F12: 60 | G12: 20 | H12: -0.3333 | I12: 1 | J12: -1 | K12: 2 | L12: =COUNTIFS('데이터 기록표'!$A$7:$A$78,$A12,'데이터 기록표'!$B$7:$B$78,$C12,'데이터 기록표'!$G$7:$G$78,"<>") -> 3 | M12: =IFERROR(AVERAGEIFS('데이터 기록표'!$J$7:$J$78,'데이터 기록표'!$A$7:$A$78,$A12,'데이터 기록표'!$B$7:$B$78,$C12),"") -> 87.314351 | N12: =IFERROR(AVERAGEIFS('데이터 기록표'!$K$7:$K$78,'데이터 기록표'!$A$7:$A$78,$A12,'데이터 기록표'!$B$7:$B$78,$C12),"") -> 25.890096 | O12: =IFERROR(AVERAGEIFS('데이터 기록표'!$L$7:$L$78,'데이터 기록표'!$A$7:$A$78,$A12,'데이터 기록표'!$B$7:$B$78,$C12),"") | P12: =IFERROR(AVERAGEIFS('데이터 기록표'!$M$7:$M$78,'데이터 기록표'!$A$7:$A$78,$A12,'데이터 기록표'!$B$7:$B$78,$C12),"") -> 0 | Q12: =IFERROR(AVERAGEIFS('데이터 기록표'!$N$7:$N$78,'데이터 기록표'!$A$7:$A$78,$A12,'데이터 기록표'!$B$7:$B$78,$C12),"") -> 0 | R12: =IFERROR(AVERAGEIFS('데이터 기록표'!$O$7:$O$78,'데이터 기록표'!$A$7:$A$78,$A12,'데이터 기록표'!$B$7:$B$78,$C12),"") -> 76.24
A13: 7 | B13: 8 | C13: 고정측 | D13: 4×4 | E13: 223 | F13: 60 | G13: 80 | H13: -0.3333 | I13: 1 | J13: 1 | K13: 2 | L13: =COUNTIFS('데이터 기록표'!$A$7:$A$78,$A13,'데이터 기록표'!$B$7:$B$78,$C13,'데이터 기록표'!$G$7:$G$78,"<>") -> 3 | M13: =IFERROR(AVERAGEIFS('데이터 기록표'!$J$7:$J$78,'데이터 기록표'!$A$7:$A$78,$A13,'데이터 기록표'!$B$7:$B$78,$C13),"") -> 95.921665 | N13: =IFERROR(AVERAGEIFS('데이터 기록표'!$K$7:$K$78,'데이터 기록표'!$A$7:$A$78,$A13,'데이터 기록표'!$B$7:$B$78,$C13),"") -> 2.541097 | O13: =IFERROR(AVERAGEIFS('데이터 기록표'!$L$7:$L$78,'데이터 기록표'!$A$7:$A$78,$A13,'데이터 기록표'!$B$7:$B$78,$C13),"") | P13: =IFERROR(AVERAGEIFS('데이터 기록표'!$M$7:$M$78,'데이터 기록표'!$A$7:$A$78,$A13,'데이터 기록표'!$B$7:$B$78,$C13),"") -> 0 | Q13: =IFERROR(AVERAGEIFS('데이터 기록표'!$N$7:$N$78,'데이터 기록표'!$A$7:$A$78,$A13,'데이터 기록표'!$B$7:$B$78,$C13),"") -> 0 | R13: =IFERROR(AVERAGEIFS('데이터 기록표'!$O$7:$O$78,'데이터 기록표'!$A$7:$A$78,$A13,'데이터 기록표'!$B$7:$B$78,$C13),"") -> 78.64
A14: 8 | B14: 7 | C14: 고정측 | D14: 4×4 | E14: 223 | F14: 60 | G14: 60 | H14: -0.3333 | I14: 1 | J14: 0.3333 | K14: 2 | L14: =COUNTIFS('데이터 기록표'!$A$7:$A$78,$A14,'데이터 기록표'!$B$7:$B$78,$C14,'데이터 기록표'!$G$7:$G$78,"<>") -> 3 | M14: =IFERROR(AVERAGEIFS('데이터 기록표'!$J$7:$J$78,'데이터 기록표'!$A$7:$A$78,$A14,'데이터 기록표'!$B$7:$B$78,$C14),"") -> 96.553379 | N14: =IFERROR(AVERAGEIFS('데이터 기록표'!$K$7:$K$78,'데이터 기록표'!$A$7:$A$78,$A14,'데이터 기록표'!$B$7:$B$78,$C14),"") -> 1.4994303 | O14: =IFERROR(AVERAGEIFS('데이터 기록표'!$L$7:$L$78,'데이터 기록표'!$A$7:$A$78,$A14,'데이터 기록표'!$B$7:$B$78,$C14),"") | P14: =IFERROR(AVERAGEIFS('데이터 기록표'!$M$7:$M$78,'데이터 기록표'!$A$7:$A$78,$A14,'데이터 기록표'!$B$7:$B$78,$C14),"") -> 0 | Q14: =IFERROR(AVERAGEIFS('데이터 기록표'!$N$7:$N$78,'데이터 기록표'!$A$7:$A$78,$A14,'데이터 기록표'!$B$7:$B$78,$C14),"") -> 0 | R14: =IFERROR(AVERAGEIFS('데이터 기록표'!$O$7:$O$78,'데이터 기록표'!$A$7:$A$78,$A14,'데이터 기록표'!$B$7:$B$78,$C14),"") -> 77.31
A15: 9 | B15: 9 | C15: 고정측 | D15: 4×4 | E15: 237 | F15: 60 | G15: 20 | H15: 0.3333 | I15: 1 | J15: -1 | K15: 3 | L15: =COUNTIFS('데이터 기록표'!$A$7:$A$78,$A15,'데이터 기록표'!$B$7:$B$78,$C15,'데이터 기록표'!$G$7:$G$78,"<>") -> 3 | M15: =IFERROR(AVERAGEIFS('데이터 기록표'!$J$7:$J$78,'데이터 기록표'!$A$7:$A$78,$A15,'데이터 기록표'!$B$7:$B$78,$C15),"") -> 90.686544 | N15: =IFERROR(AVERAGEIFS('데이터 기록표'!$K$7:$K$78,'데이터 기록표'!$A$7:$A$78,$A15,'데이터 기록표'!$B$7:$B$78,$C15),"") -> 12.661743 | O15: =IFERROR(AVERAGEIFS('데이터 기록표'!$L$7:$L$78,'데이터 기록표'!$A$7:$A$78,$A15,'데이터 기록표'!$B$7:$B$78,$C15),"") | P15: =IFERROR(AVERAGEIFS('데이터 기록표'!$M$7:$M$78,'데이터 기록표'!$A$7:$A$78,$A15,'데이터 기록표'!$B$7:$B$78,$C15),"") -> 0 | Q15: =IFERROR(AVERAGEIFS('데이터 기록표'!$N$7:$N$78,'데이터 기록표'!$A$7:$A$78,$A15,'데이터 기록표'!$B$7:$B$78,$C15),"") -> 0 | R15: =IFERROR(AVERAGEIFS('데이터 기록표'!$O$7:$O$78,'데이터 기록표'!$A$7:$A$78,$A15,'데이터 기록표'!$B$7:$B$78,$C15),"") -> 75.496667
A16: 10 | B16: 10 | C16: 고정측 | D16: 4×4 | E16: 237 | F16: 60 | G16: 40 | H16: 0.3333 | I16: 1 | J16: -0.3333 | K16: 3 | L16: =COUNTIFS('데이터 기록표'!$A$7:$A$78,$A16,'데이터 기록표'!$B$7:$B$78,$C16,'데이터 기록표'!$G$7:$G$78,"<>") -> 3 | M16: =IFERROR(AVERAGEIFS('데이터 기록표'!$J$7:$J$78,'데이터 기록표'!$A$7:$A$78,$A16,'데이터 기록표'!$B$7:$B$78,$C16),"") -> 95.763143 | N16: =IFERROR(AVERAGEIFS('데이터 기록표'!$K$7:$K$78,'데이터 기록표'!$A$7:$A$78,$A16,'데이터 기록표'!$B$7:$B$78,$C16),"") -> 4.401652 | O16: =IFERROR(AVERAGEIFS('데이터 기록표'!$L$7:$L$78,'데이터 기록표'!$A$7:$A$78,$A16,'데이터 기록표'!$B$7:$B$78,$C16),"") | P16: =IFERROR(AVERAGEIFS('데이터 기록표'!$M$7:$M$78,'데이터 기록표'!$A$7:$A$78,$A16,'데이터 기록표'!$B$7:$B$78,$C16),"") -> 0 | Q16: =IFERROR(AVERAGEIFS('데이터 기록표'!$N$7:$N$78,'데이터 기록표'!$A$7:$A$78,$A16,'데이터 기록표'!$B$7:$B$78,$C16),"") -> 0 | R16: =IFERROR(AVERAGEIFS('데이터 기록표'!$O$7:$O$78,'데이터 기록표'!$A$7:$A$78,$A16,'데이터 기록표'!$B$7:$B$78,$C16),"") -> 76.05
A17: 11 | B17: 12 | C17: 고정측 | D17: 4×4 | E17: 237 | F17: 60 | G17: 80 | H17: 0.3333 | I17: 1 | J17: 1 | K17: 3 | L17: =COUNTIFS('데이터 기록표'!$A$7:$A$78,$A17,'데이터 기록표'!$B$7:$B$78,$C17,'데이터 기록표'!$G$7:$G$78,"<>") -> 3 | M17: =IFERROR(AVERAGEIFS('데이터 기록표'!$J$7:$J$78,'데이터 기록표'!$A$7:$A$78,$A17,'데이터 기록표'!$B$7:$B$78,$C17),"") -> 97.05285 | N17: =IFERROR(AVERAGEIFS('데이터 기록표'!$K$7:$K$78,'데이터 기록표'!$A$7:$A$78,$A17,'데이터 기록표'!$B$7:$B$78,$C17),"") -> 0.67596436 | O17: =IFERROR(AVERAGEIFS('데이터 기록표'!$L$7:$L$78,'데이터 기록표'!$A$7:$A$78,$A17,'데이터 기록표'!$B$7:$B$78,$C17),"") | P17: =IFERROR(AVERAGEIFS('데이터 기록표'!$M$7:$M$78,'데이터 기록표'!$A$7:$A$78,$A17,'데이터 기록표'!$B$7:$B$78,$C17),"") -> 0 | Q17: =IFERROR(AVERAGEIFS('데이터 기록표'!$N$7:$N$78,'데이터 기록표'!$A$7:$A$78,$A17,'데이터 기록표'!$B$7:$B$78,$C17),"") -> 0 | R17: =IFERROR(AVERAGEIFS('데이터 기록표'!$O$7:$O$78,'데이터 기록표'!$A$7:$A$78,$A17,'데이터 기록표'!$B$7:$B$78,$C17),"") -> 76.9
A18: 12 | B18: 11 | C18: 고정측 | D18: 4×4 | E18: 237 | F18: 60 | G18: 60 | H18: 0.3333 | I18: 1 | J18: 0.3333 | K18: 3 | L18: =COUNTIFS('데이터 기록표'!$A$7:$A$78,$A18,'데이터 기록표'!$B$7:$B$78,$C18,'데이터 기록표'!$G$7:$G$78,"<>") -> 3 | M18: =IFERROR(AVERAGEIFS('데이터 기록표'!$J$7:$J$78,'데이터 기록표'!$A$7:$A$78,$A18,'데이터 기록표'!$B$7:$B$78,$C18),"") -> 97.140164 | N18: =IFERROR(AVERAGEIFS('데이터 기록표'!$K$7:$K$78,'데이터 기록표'!$A$7:$A$78,$A18,'데이터 기록표'!$B$7:$B$78,$C18),"") -> 1.2461344 | O18: =IFERROR(AVERAGEIFS('데이터 기록표'!$L$7:$L$78,'데이터 기록표'!$A$7:$A$78,$A18,'데이터 기록표'!$B$7:$B$78,$C18),"") | P18: =IFERROR(AVERAGEIFS('데이터 기록표'!$M$7:$M$78,'데이터 기록표'!$A$7:$A$78,$A18,'데이터 기록표'!$B$7:$B$78,$C18),"") -> 0 | Q18: =IFERROR(AVERAGEIFS('데이터 기록표'!$N$7:$N$78,'데이터 기록표'!$A$7:$A$78,$A18,'데이터 기록표'!$B$7:$B$78,$C18),"") -> 0 | R18: =IFERROR(AVERAGEIFS('데이터 기록표'!$O$7:$O$78,'데이터 기록표'!$A$7:$A$78,$A18,'데이터 기록표'!$B$7:$B$78,$C18),"") -> 76.57
A19: 13 | B19: 13 | C19: 고정측 | D19: 4×4 + 2² 꼭짓점 | E19: 250 | F19: 60 | G19: 20 | H19: 1 | I19: 1 | J19: -1 | K19: 4 | L19: =COUNTIFS('데이터 기록표'!$A$7:$A$78,$A19,'데이터 기록표'!$B$7:$B$78,$C19,'데이터 기록표'!$G$7:$G$78,"<>") -> 3 | M19: =IFERROR(AVERAGEIFS('데이터 기록표'!$J$7:$J$78,'데이터 기록표'!$A$7:$A$78,$A19,'데이터 기록표'!$B$7:$B$78,$C19),"") -> 92.360602 | N19: =IFERROR(AVERAGEIFS('데이터 기록표'!$K$7:$K$78,'데이터 기록표'!$A$7:$A$78,$A19,'데이터 기록표'!$B$7:$B$78,$C19),"") -> 9.2229207 | O19: =IFERROR(AVERAGEIFS('데이터 기록표'!$L$7:$L$78,'데이터 기록표'!$A$7:$A$78,$A19,'데이터 기록표'!$B$7:$B$78,$C19),"") | P19: =IFERROR(AVERAGEIFS('데이터 기록표'!$M$7:$M$78,'데이터 기록표'!$A$7:$A$78,$A19,'데이터 기록표'!$B$7:$B$78,$C19),"") -> 0 | Q19: =IFERROR(AVERAGEIFS('데이터 기록표'!$N$7:$N$78,'데이터 기록표'!$A$7:$A$78,$A19,'데이터 기록표'!$B$7:$B$78,$C19),"") -> 0 | R19: =IFERROR(AVERAGEIFS('데이터 기록표'!$O$7:$O$78,'데이터 기록표'!$A$7:$A$78,$A19,'데이터 기록표'!$B$7:$B$78,$C19),"") -> 75.273333
A20: 13 | B20: 13 | C20: 이동측 | D20: 2² M2 | E20: 250 | F20: 60 | G20: 20 | H20: 1 | I20: 1 | J20: -1 | K20: 4 | L20: =COUNTIFS('데이터 기록표'!$A$7:$A$78,$A20,'데이터 기록표'!$B$7:$B$78,$C20,'데이터 기록표'!$G$7:$G$78,"<>") -> 3 | M20: =IFERROR(AVERAGEIFS('데이터 기록표'!$J$7:$J$78,'데이터 기록표'!$A$7:$A$78,$A20,'데이터 기록표'!$B$7:$B$78,$C20),"") -> 95.081414 | N20: =IFERROR(AVERAGEIFS('데이터 기록표'!$K$7:$K$78,'데이터 기록표'!$A$7:$A$78,$A20,'데이터 기록표'!$B$7:$B$78,$C20),"") -> 4.8558553 | O20: =IFERROR(AVERAGEIFS('데이터 기록표'!$L$7:$L$78,'데이터 기록표'!$A$7:$A$78,$A20,'데이터 기록표'!$B$7:$B$78,$C20),"") | P20: =IFERROR(AVERAGEIFS('데이터 기록표'!$M$7:$M$78,'데이터 기록표'!$A$7:$A$78,$A20,'데이터 기록표'!$B$7:$B$78,$C20),"") -> 0 | Q20: =IFERROR(AVERAGEIFS('데이터 기록표'!$N$7:$N$78,'데이터 기록표'!$A$7:$A$78,$A20,'데이터 기록표'!$B$7:$B$78,$C20),"") -> 0 | R20: =IFERROR(AVERAGEIFS('데이터 기록표'!$O$7:$O$78,'데이터 기록표'!$A$7:$A$78,$A20,'데이터 기록표'!$B$7:$B$78,$C20),"") -> 75.166667 | S20: =IF(OR(M19="",M20=""),"",M19-M20) -> -2.7208116 | T20: =IF(OR(O19="",O20=""),"",O19-O20) | U20: =IF(OR(R19="",R20=""),"",R19-R20) -> 0.10666667
A21: 14 | B21: 16 | C21: 고정측 | D21: 4×4 + 2² 꼭짓점 | E21: 250 | F21: 60 | G21: 80 | H21: 1 | I21: 1 | J21: 1 | K21: 4 | L21: =COUNTIFS('데이터 기록표'!$A$7:$A$78,$A21,'데이터 기록표'!$B$7:$B$78,$C21,'데이터 기록표'!$G$7:$G$78,"<>") -> 3 | M21: =IFERROR(AVERAGEIFS('데이터 기록표'!$J$7:$J$78,'데이터 기록표'!$A$7:$A$78,$A21,'데이터 기록표'!$B$7:$B$78,$C21),"") -> 96.342468 | N21: =IFERROR(AVERAGEIFS('데이터 기록표'!$K$7:$K$78,'데이터 기록표'!$A$7:$A$78,$A21,'데이터 기록표'!$B$7:$B$78,$C21),"") -> 1.4307658 | O21: =IFERROR(AVERAGEIFS('데이터 기록표'!$L$7:$L$78,'데이터 기록표'!$A$7:$A$78,$A21,'데이터 기록표'!$B$7:$B$78,$C21),"") | P21: =IFERROR(AVERAGEIFS('데이터 기록표'!$M$7:$M$78,'데이터 기록표'!$A$7:$A$78,$A21,'데이터 기록표'!$B$7:$B$78,$C21),"") -> 0 | Q21: =IFERROR(AVERAGEIFS('데이터 기록표'!$N$7:$N$78,'데이터 기록표'!$A$7:$A$78,$A21,'데이터 기록표'!$B$7:$B$78,$C21),"") -> 0 | R21: =IFERROR(AVERAGEIFS('데이터 기록표'!$O$7:$O$78,'데이터 기록표'!$A$7:$A$78,$A21,'데이터 기록표'!$B$7:$B$78,$C21),"") -> 76.216667
A22: 14 | B22: 16 | C22: 이동측 | D22: 2² M4 | E22: 250 | F22: 60 | G22: 80 | H22: 1 | I22: 1 | J22: 1 | K22: 4 | L22: =COUNTIFS('데이터 기록표'!$A$7:$A$78,$A22,'데이터 기록표'!$B$7:$B$78,$C22,'데이터 기록표'!$G$7:$G$78,"<>") -> 0 | M22: =IFERROR(AVERAGEIFS('데이터 기록표'!$J$7:$J$78,'데이터 기록표'!$A$7:$A$78,$A22,'데이터 기록표'!$B$7:$B$78,$C22),"") | N22: =IFERROR(AVERAGEIFS('데이터 기록표'!$K$7:$K$78,'데이터 기록표'!$A$7:$A$78,$A22,'데이터 기록표'!$B$7:$B$78,$C22),"") | O22: =IFERROR(AVERAGEIFS('데이터 기록표'!$L$7:$L$78,'데이터 기록표'!$A$7:$A$78,$A22,'데이터 기록표'!$B$7:$B$78,$C22),"") | P22: =IFERROR(AVERAGEIFS('데이터 기록표'!$M$7:$M$78,'데이터 기록표'!$A$7:$A$78,$A22,'데이터 기록표'!$B$7:$B$78,$C22),"") -> 0 | Q22: =IFERROR(AVERAGEIFS('데이터 기록표'!$N$7:$N$78,'데이터 기록표'!$A$7:$A$78,$A22,'데이터 기록표'!$B$7:$B$78,$C22),"") -> 0 | R22: =IFERROR(AVERAGEIFS('데이터 기록표'!$O$7:$O$78,'데이터 기록표'!$A$7:$A$78,$A22,'데이터 기록표'!$B$7:$B$78,$C22),"") -> 76.103333 | S22: =IF(OR(M21="",M22=""),"",M21-M22) | T22: =IF(OR(O21="",O22=""),"",O21-O22) | U22: =IF(OR(R21="",R22=""),"",R21-R22) -> 0.11333333
A23: 15 | B23: 15 | C23: 고정측 | D23: 4×4 | E23: 250 | F23: 60 | G23: 60 | H23: 1 | I23: 1 | J23: 0.3333 | K23: 4 | L23: =COUNTIFS('데이터 기록표'!$A$7:$A$78,$A23,'데이터 기록표'!$B$7:$B$78,$C23,'데이터 기록표'!$G$7:$G$78,"<>") -> 3 | M23: =IFERROR(AVERAGEIFS('데이터 기록표'!$J$7:$J$78,'데이터 기록표'!$A$7:$A$78,$A23,'데이터 기록표'!$B$7:$B$78,$C23),"") -> 96.809387 | N23: =IFERROR(AVERAGEIFS('데이터 기록표'!$K$7:$K$78,'데이터 기록표'!$A$7:$A$78,$A23,'데이터 기록표'!$B$7:$B$78,$C23),"") -> 2.8711955 | O23: =IFERROR(AVERAGEIFS('데이터 기록표'!$L$7:$L$78,'데이터 기록표'!$A$7:$A$78,$A23,'데이터 기록표'!$B$7:$B$78,$C23),"") | P23: =IFERROR(AVERAGEIFS('데이터 기록표'!$M$7:$M$78,'데이터 기록표'!$A$7:$A$78,$A23,'데이터 기록표'!$B$7:$B$78,$C23),"") -> 0 | Q23: =IFERROR(AVERAGEIFS('데이터 기록표'!$N$7:$N$78,'데이터 기록표'!$A$7:$A$78,$A23,'데이터 기록표'!$B$7:$B$78,$C23),"") -> 0 | R23: =IFERROR(AVERAGEIFS('데이터 기록표'!$O$7:$O$78,'데이터 기록표'!$A$7:$A$78,$A23,'데이터 기록표'!$B$7:$B$78,$C23),"") -> 75.966667
A24: 16 | B24: 14 | C24: 고정측 | D24: 4×4 | E24: 250 | F24: 60 | G24: 40 | H24: 1 | I24: 1 | J24: -0.3333 | K24: 4 | L24: =COUNTIFS('데이터 기록표'!$A$7:$A$78,$A24,'데이터 기록표'!$B$7:$B$78,$C24,'데이터 기록표'!$G$7:$G$78,"<>") -> 3 | M24: =IFERROR(AVERAGEIFS('데이터 기록표'!$J$7:$J$78,'데이터 기록표'!$A$7:$A$78,$A24,'데이터 기록표'!$B$7:$B$78,$C24),"") -> 96.337721 | N24: =IFERROR(AVERAGEIFS('데이터 기록표'!$K$7:$K$78,'데이터 기록표'!$A$7:$A$78,$A24,'데이터 기록표'!$B$7:$B$78,$C24),"") -> 4.5674642 | O24: =IFERROR(AVERAGEIFS('데이터 기록표'!$L$7:$L$78,'데이터 기록표'!$A$7:$A$78,$A24,'데이터 기록표'!$B$7:$B$78,$C24),"") | P24: =IFERROR(AVERAGEIFS('데이터 기록표'!$M$7:$M$78,'데이터 기록표'!$A$7:$A$78,$A24,'데이터 기록표'!$B$7:$B$78,$C24),"") -> 0 | Q24: =IFERROR(AVERAGEIFS('데이터 기록표'!$N$7:$N$78,'데이터 기록표'!$A$7:$A$78,$A24,'데이터 기록표'!$B$7:$B$78,$C24),"") -> 0 | R24: =IFERROR(AVERAGEIFS('데이터 기록표'!$O$7:$O$78,'데이터 기록표'!$A$7:$A$78,$A24,'데이터 기록표'!$B$7:$B$78,$C24),"") -> 75.61
A25: 17 | B25: 20 | C25: 고정측 | D25: 40℃ 추가 | E25: 250 | F25: 40 | G25: 80 | H25: 1 | I25: -1 | J25: 1 | K25: 4 | L25: =COUNTIFS('데이터 기록표'!$A$7:$A$78,$A25,'데이터 기록표'!$B$7:$B$78,$C25,'데이터 기록표'!$G$7:$G$78,"<>") -> 3 | M25: =IFERROR(AVERAGEIFS('데이터 기록표'!$J$7:$J$78,'데이터 기록표'!$A$7:$A$78,$A25,'데이터 기록표'!$B$7:$B$78,$C25),"") -> 96.697659 | N25: =IFERROR(AVERAGEIFS('데이터 기록표'!$K$7:$K$78,'데이터 기록표'!$A$7:$A$78,$A25,'데이터 기록표'!$B$7:$B$78,$C25),"") -> 1.2039185 | O25: =IFERROR(AVERAGEIFS('데이터 기록표'!$L$7:$L$78,'데이터 기록표'!$A$7:$A$78,$A25,'데이터 기록표'!$B$7:$B$78,$C25),"") | P25: =IFERROR(AVERAGEIFS('데이터 기록표'!$M$7:$M$78,'데이터 기록표'!$A$7:$A$78,$A25,'데이터 기록표'!$B$7:$B$78,$C25),"") -> 0 | Q25: =IFERROR(AVERAGEIFS('데이터 기록표'!$N$7:$N$78,'데이터 기록표'!$A$7:$A$78,$A25,'데이터 기록표'!$B$7:$B$78,$C25),"") -> 0 | R25: =IFERROR(AVERAGEIFS('데이터 기록표'!$O$7:$O$78,'데이터 기록표'!$A$7:$A$78,$A25,'데이터 기록표'!$B$7:$B$78,$C25),"") -> 77.086667
A26: 18 | B26: 19 | C26: 고정측 | D26: 40℃ 추가 | E26: 237 | F26: 40 | G26: 80 | H26: 0.3333 | I26: -1 | J26: 1 | K26: 3 | L26: =COUNTIFS('데이터 기록표'!$A$7:$A$78,$A26,'데이터 기록표'!$B$7:$B$78,$C26,'데이터 기록표'!$G$7:$G$78,"<>") -> 3 | M26: =IFERROR(AVERAGEIFS('데이터 기록표'!$J$7:$J$78,'데이터 기록표'!$A$7:$A$78,$A26,'데이터 기록표'!$B$7:$B$78,$C26),"") -> 96.787347 | N26: =IFERROR(AVERAGEIFS('데이터 기록표'!$K$7:$K$78,'데이터 기록표'!$A$7:$A$78,$A26,'데이터 기록표'!$B$7:$B$78,$C26),"") -> 1.4266968 | O26: =IFERROR(AVERAGEIFS('데이터 기록표'!$L$7:$L$78,'데이터 기록표'!$A$7:$A$78,$A26,'데이터 기록표'!$B$7:$B$78,$C26),"") | P26: =IFERROR(AVERAGEIFS('데이터 기록표'!$M$7:$M$78,'데이터 기록표'!$A$7:$A$78,$A26,'데이터 기록표'!$B$7:$B$78,$C26),"") -> 0 | Q26: =IFERROR(AVERAGEIFS('데이터 기록표'!$N$7:$N$78,'데이터 기록표'!$A$7:$A$78,$A26,'데이터 기록표'!$B$7:$B$78,$C26),"") -> 0 | R26: =IFERROR(AVERAGEIFS('데이터 기록표'!$O$7:$O$78,'데이터 기록표'!$A$7:$A$78,$A26,'데이터 기록표'!$B$7:$B$78,$C26),"") -> 78.223333
A27: 19 | B27: 18 | C27: 고정측 | D27: 40℃ 추가 | E27: 223 | F27: 40 | G27: 80 | H27: -0.3333 | I27: -1 | J27: 1 | K27: 2 | L27: =COUNTIFS('데이터 기록표'!$A$7:$A$78,$A27,'데이터 기록표'!$B$7:$B$78,$C27,'데이터 기록표'!$G$7:$G$78,"<>") -> 3 | M27: =IFERROR(AVERAGEIFS('데이터 기록표'!$J$7:$J$78,'데이터 기록표'!$A$7:$A$78,$A27,'데이터 기록표'!$B$7:$B$78,$C27),"") -> 96.423848 | N27: =IFERROR(AVERAGEIFS('데이터 기록표'!$K$7:$K$78,'데이터 기록표'!$A$7:$A$78,$A27,'데이터 기록표'!$B$7:$B$78,$C27),"") -> 1.2883504 | O27: =IFERROR(AVERAGEIFS('데이터 기록표'!$L$7:$L$78,'데이터 기록표'!$A$7:$A$78,$A27,'데이터 기록표'!$B$7:$B$78,$C27),"") | P27: =IFERROR(AVERAGEIFS('데이터 기록표'!$M$7:$M$78,'데이터 기록표'!$A$7:$A$78,$A27,'데이터 기록표'!$B$7:$B$78,$C27),"") -> 1 | Q27: =IFERROR(AVERAGEIFS('데이터 기록표'!$N$7:$N$78,'데이터 기록표'!$A$7:$A$78,$A27,'데이터 기록표'!$B$7:$B$78,$C27),"") -> 0 | R27: =IFERROR(AVERAGEIFS('데이터 기록표'!$O$7:$O$78,'데이터 기록표'!$A$7:$A$78,$A27,'데이터 기록표'!$B$7:$B$78,$C27),"") -> 79.94
A28: 20 | B28: 17 | C28: 고정측 | D28: 40℃ 추가 | E28: 210 | F28: 40 | G28: 80 | H28: -1 | I28: -1 | J28: 1 | K28: 1 | L28: =COUNTIFS('데이터 기록표'!$A$7:$A$78,$A28,'데이터 기록표'!$B$7:$B$78,$C28,'데이터 기록표'!$G$7:$G$78,"<>") -> 3 | M28: =IFERROR(AVERAGEIFS('데이터 기록표'!$J$7:$J$78,'데이터 기록표'!$A$7:$A$78,$A28,'데이터 기록표'!$B$7:$B$78,$C28),"") -> 96.381972 | N28: =IFERROR(AVERAGEIFS('데이터 기록표'!$K$7:$K$78,'데이터 기록표'!$A$7:$A$78,$A28,'데이터 기록표'!$B$7:$B$78,$C28),"") -> 3.1565348 | O28: =IFERROR(AVERAGEIFS('데이터 기록표'!$L$7:$L$78,'데이터 기록표'!$A$7:$A$78,$A28,'데이터 기록표'!$B$7:$B$78,$C28),"") | P28: =IFERROR(AVERAGEIFS('데이터 기록표'!$M$7:$M$78,'데이터 기록표'!$A$7:$A$78,$A28,'데이터 기록표'!$B$7:$B$78,$C28),"") -> 1 | Q28: =IFERROR(AVERAGEIFS('데이터 기록표'!$N$7:$N$78,'데이터 기록표'!$A$7:$A$78,$A28,'데이터 기록표'!$B$7:$B$78,$C28),"") -> 0 | R28: =IFERROR(AVERAGEIFS('데이터 기록표'!$O$7:$O$78,'데이터 기록표'!$A$7:$A$78,$A28,'데이터 기록표'!$B$7:$B$78,$C28),"") -> 81.83
A30: 행 수 확인 | C30: =COUNTA(A5:A28) -> 24 | D30: / 24
A31: ※ 함침율 3점 범위 평균 = 각 시편의 (P1–P3 최대 − 최소)를 샷 평균한 값(시편 내 불균일도). 파팅면 차이 = 고정측 − 이동측 (이동측 행에 표시).
A33: 금형온도 짝 비교 (고정측, 사출속도 80 mm/s): 60℃ 런 − 40℃ 런
A34: 핫러너 온도 (℃) | B34: 60℃ 런 (실행순서) | C34: 40℃ 런 (실행순서) | D34: 함침율 60℃ (%) | E34: 함침율 40℃ (%) | F34: Δ함침율 (60−40, %p) | G34: 인장 60℃ (MPa) | H34: 인장 40℃ (MPa) | I34: Δ인장 (MPa) | J34: 무게 60℃ (g) | K34: 무게 40℃ (g) | L34: Δ무게 (g)
A35: 210 | B35: 4 | C35: 20 | D35: =IF(M9="","",M9) -> 96.502855 | E35: =IF(M28="","",M28) -> 96.381972 | F35: =IF(OR(D35="",E35=""),"",D35-E35) -> 0.12088352 | G35: =IF(O9="","",O9) | H35: =IF(O28="","",O28) | I35: =IF(OR(G35="",H35=""),"",G35-H35) | J35: =IF(R9="","",R9) -> 82.406667 | K35: =IF(R28="","",R28) -> 81.83 | L35: =IF(OR(J35="",K35=""),"",J35-K35) -> 0.57666667
A36: 223 | B36: 7 | C36: 19 | D36: =IF(M13="","",M13) -> 95.921665 | E36: =IF(M27="","",M27) -> 96.423848 | F36: =IF(OR(D36="",E36=""),"",D36-E36) -> -0.5021837 | G36: =IF(O13="","",O13) | H36: =IF(O27="","",O27) | I36: =IF(OR(G36="",H36=""),"",G36-H36) | J36: =IF(R13="","",R13) -> 78.64 | K36: =IF(R27="","",R27) -> 79.94 | L36: =IF(OR(J36="",K36=""),"",J36-K36) -> -1.3
A37: 237 | B37: 11 | C37: 18 | D37: =IF(M17="","",M17) -> 97.05285 | E37: =IF(M26="","",M26) -> 96.787347 | F37: =IF(OR(D37="",E37=""),"",D37-E37) -> 0.26550293 | G37: =IF(O17="","",O17) | H37: =IF(O26="","",O26) | I37: =IF(OR(G37="",H37=""),"",G37-H37) | J37: =IF(R17="","",R17) -> 76.9 | K37: =IF(R26="","",R26) -> 78.223333 | L37: =IF(OR(J37="",K37=""),"",J37-K37) -> -1.3233333
A38: 250 | B38: 14 | C38: 17 | D38: =IF(M21="","",M21) -> 96.342468 | E38: =IF(M25="","",M25) -> 96.697659 | F38: =IF(OR(D38="",E38=""),"",D38-E38) -> -0.3551907 | G38: =IF(O21="","",O21) | H38: =IF(O25="","",O25) | I38: =IF(OR(G38="",H38=""),"",G38-H38) | J38: =IF(R21="","",R21) -> 76.216667 | K38: =IF(R25="","",R25) -> 77.086667 | L38: =IF(OR(J38="",K38=""),"",J38-K38) -> -0.87
A39: ※ 4개 Δ값의 평균이 금형온도 주효과(속도 80 조건), Δ값이 온도에 따라 달라지면 금형온도×핫러너 온도 교호작용의 징후.
